<robot name="simple_robot">
  <link name="world"/>
  <link name="link1">
		<visual>
		    <origin xyz="0 0 0.0425" rpy="0 0 0"/>
			<geometry>
				<box size="0.32 0.26 0.085"/>
			</geometry>
			<material name="Cyan1">
	       		<color rgba="0 0.9 0.9 1.0"/>
	     	</material>
		</visual>	
  </link>

  <link name="link2">
		<visual>
		    <origin xyz="0 0 0.0425" rpy="0 0 0"/>
			<geometry>
				<box size="0.32 0.26 0.085"/>
			</geometry>
			<material name="Cyan1">
	       		<color rgba="0 0.9 0.9 1.0"/>
	     	</material>
		</visual>	
  </link>

 	<joint name="joint1" type="revolute">
    	<parent link="world"/>
    	<child link="link1"/>
    	<origin xyz="0 0 0" rpy="0 0 0"/>
      <axis xyz="1 0 0"/>
	</joint>

 	<joint name="joint2" type="revolute">
    	<parent link="link1"/>
    	<child link="link2"/>
    	<origin xyz="0 0 1" rpy="0 0 0"/>
      <axis xyz="1 0 0"/>
	</joint>

</robot>
